2018-12-16 14:52:41,127 ERROR: Exception on /search [GET] [in c:\users\nirajc\envs\microblog\lib\site-packages\flask\app.py:1761]
Traceback (most recent call last):
  File "c:\users\nirajc\envs\microblog\lib\site-packages\urllib3\connection.py", line 159, in _new_conn
    (self._dns_host, self.port), self.timeout, **extra_kw)
  File "c:\users\nirajc\envs\microblog\lib\site-packages\urllib3\util\connection.py", line 80, in create_connection
    raise err
  File "c:\users\nirajc\envs\microblog\lib\site-packages\urllib3\util\connection.py", line 70, in create_connection
    sock.connect(sa)
ConnectionRefusedError: [WinError 10061] No connection could be made because the target machine actively refused it

During handling of the above exception, another exception occurred:

Traceback (most recent call last):
  File "c:\users\nirajc\envs\microblog\lib\site-packages\elasticsearch\connection\http_urllib3.py", line 172, in perform_request
    response = self.pool.urlopen(method, url, body, retries=Retry(False), headers=request_headers, **kw)
  File "c:\users\nirajc\envs\microblog\lib\site-packages\urllib3\connectionpool.py", line 638, in urlopen
    _stacktrace=sys.exc_info()[2])
  File "c:\users\nirajc\envs\microblog\lib\site-packages\urllib3\util\retry.py", line 343, in increment
    raise six.reraise(type(error), error, _stacktrace)
  File "c:\users\nirajc\envs\microblog\lib\site-packages\urllib3\packages\six.py", line 686, in reraise
    raise value
  File "c:\users\nirajc\envs\microblog\lib\site-packages\urllib3\connectionpool.py", line 600, in urlopen
    chunked=chunked)
  File "c:\users\nirajc\envs\microblog\lib\site-packages\urllib3\connectionpool.py", line 354, in _make_request
    conn.request(method, url, **httplib_request_kw)
  File "c:\program files (x86)\python37-32\Lib\http\client.py", line 1229, in request
    self._send_request(method, url, body, headers, encode_chunked)
  File "c:\program files (x86)\python37-32\Lib\http\client.py", line 1275, in _send_request
    self.endheaders(body, encode_chunked=encode_chunked)
  File "c:\program files (x86)\python37-32\Lib\http\client.py", line 1224, in endheaders
    self._send_output(message_body, encode_chunked=encode_chunked)
  File "c:\program files (x86)\python37-32\Lib\http\client.py", line 1016, in _send_output
    self.send(msg)
  File "c:\program files (x86)\python37-32\Lib\http\client.py", line 956, in send
    self.connect()
  File "c:\users\nirajc\envs\microblog\lib\site-packages\urllib3\connection.py", line 181, in connect
    conn = self._new_conn()
  File "c:\users\nirajc\envs\microblog\lib\site-packages\urllib3\connection.py", line 168, in _new_conn
    self, "Failed to establish a new connection: %s" % e)
urllib3.exceptions.NewConnectionError: <urllib3.connection.HTTPConnection object at 0x07909750>: Failed to establish a new connection: [WinError 10061] No connection could be made because the target machine actively refused it

During handling of the above exception, another exception occurred:

Traceback (most recent call last):
  File "c:\users\nirajc\envs\microblog\lib\site-packages\flask\app.py", line 2292, in wsgi_app
    response = self.full_dispatch_request()
  File "c:\users\nirajc\envs\microblog\lib\site-packages\flask\app.py", line 1815, in full_dispatch_request
    rv = self.handle_user_exception(e)
  File "c:\users\nirajc\envs\microblog\lib\site-packages\flask\app.py", line 1718, in handle_user_exception
    reraise(exc_type, exc_value, tb)
  File "c:\users\nirajc\envs\microblog\lib\site-packages\flask\_compat.py", line 35, in reraise
    raise value
  File "c:\users\nirajc\envs\microblog\lib\site-packages\flask\app.py", line 1813, in full_dispatch_request
    rv = self.dispatch_request()
  File "c:\users\nirajc\envs\microblog\lib\site-packages\flask\app.py", line 1799, in dispatch_request
    return self.view_functions[rule.endpoint](**req.view_args)
  File "c:\users\nirajc\envs\microblog\lib\site-packages\flask_login\utils.py", line 261, in decorated_view
    return func(*args, **kwargs)
  File "D:\brainstrom\microblog\app\main\routes.py", line 144, in search
    current_app.config['POSTS_PER_PAGE'])
  File "D:\brainstrom\microblog\app\models.py", line 15, in search
    ids, total = query_index(cls.__tablename__, expression, page, per_page)
  File "D:\brainstrom\microblog\app\search.py", line 26, in query_index
    'from': (page - 1) * per_page, 'size': per_page})
  File "c:\users\nirajc\envs\microblog\lib\site-packages\elasticsearch\client\utils.py", line 76, in _wrapped
    return func(*args, params=params, **kwargs)
  File "c:\users\nirajc\envs\microblog\lib\site-packages\elasticsearch\client\__init__.py", line 660, in search
    doc_type, '_search'), params=params, body=body)
  File "c:\users\nirajc\envs\microblog\lib\site-packages\elasticsearch\transport.py", line 318, in perform_request
    status, headers_response, data = connection.perform_request(method, url, params, body, headers=headers, ignore=ignore, timeout=timeout)
  File "c:\users\nirajc\envs\microblog\lib\site-packages\elasticsearch\connection\http_urllib3.py", line 181, in perform_request
    raise ConnectionError('N/A', str(e), e)
elasticsearch.exceptions.ConnectionError: ConnectionError(<urllib3.connection.HTTPConnection object at 0x07909750>: Failed to establish a new connection: [WinError 10061] No connection could be made because the target machine actively refused it) caused by: NewConnectionError(<urllib3.connection.HTTPConnection object at 0x07909750>: Failed to establish a new connection: [WinError 10061] No connection could be made because the target machine actively refused it)
2018-12-16 17:30:46,687 INFO: Microblog startup [in D:\brainstrom\microblog\app\__init__.py:77]
2018-12-16 17:33:25,300 INFO: Microblog startup [in D:\brainstrom\microblog\app\__init__.py:77]
2018-12-16 22:22:32,820 INFO: Microblog startup [in D:\brainstrom\microblog\app\__init__.py:77]
2018-12-16 22:35:12,200 INFO: Microblog startup [in D:\brainstrom\microblog\app\__init__.py:77]
2018-12-16 22:39:22,249 INFO: Microblog startup [in D:\brainstrom\microblog\app\__init__.py:77]
2018-12-16 22:42:36,515 INFO: Microblog startup [in D:\brainstrom\microblog\app\__init__.py:77]
